[24/May/2021 08:52:20] ERROR [django.request:224] Internal Server Error: /
Traceback (most recent call last):
  File "/home/ubuntu/venv/lib/python3.8/site-packages/django/core/handlers/exception.py", line 47, in inner
    response = get_response(request)
  File "/home/ubuntu/venv/lib/python3.8/site-packages/django/core/handlers/base.py", line 204, in _get_response
    response = response.render()
  File "/home/ubuntu/venv/lib/python3.8/site-packages/django/template/response.py", line 105, in render
    self.content = self.rendered_content
  File "/home/ubuntu/venv/lib/python3.8/site-packages/django/template/response.py", line 83, in rendered_content
    return template.render(context, self._request)
  File "/home/ubuntu/venv/lib/python3.8/site-packages/django/template/backends/django.py", line 61, in render
    return self.template.render(context)
  File "/home/ubuntu/venv/lib/python3.8/site-packages/django/template/base.py", line 170, in render
    return self._render(context)
  File "/home/ubuntu/venv/lib/python3.8/site-packages/django/template/base.py", line 162, in _render
    return self.nodelist.render(context)
  File "/home/ubuntu/venv/lib/python3.8/site-packages/django/template/base.py", line 938, in render
    bit = node.render_annotated(context)
  File "/home/ubuntu/venv/lib/python3.8/site-packages/django/template/base.py", line 905, in render_annotated
    return self.render(context)
  File "/home/ubuntu/venv/lib/python3.8/site-packages/django/templatetags/static.py", line 106, in render
    url = self.url(context)
  File "/home/ubuntu/venv/lib/python3.8/site-packages/django/templatetags/static.py", line 103, in url
    return self.handle_simple(path)
  File "/home/ubuntu/venv/lib/python3.8/site-packages/django/templatetags/static.py", line 118, in handle_simple
    return staticfiles_storage.url(path)
  File "/home/ubuntu/venv/lib/python3.8/site-packages/django/contrib/staticfiles/storage.py", line 147, in url
    return self._url(self.stored_name, name, force)
  File "/home/ubuntu/venv/lib/python3.8/site-packages/django/contrib/staticfiles/storage.py", line 126, in _url
    hashed_name = hashed_name_func(*args)
  File "/home/ubuntu/venv/lib/python3.8/site-packages/django/contrib/staticfiles/storage.py", line 417, in stored_name
    raise ValueError("Missing staticfiles manifest entry for '%s'" % clean_name)
ValueError: Missing staticfiles manifest entry for 'images/favicon.png'
[24/May/2021 08:52:23] ERROR [django.request:224] Internal Server Error: /
Traceback (most recent call last):
  File "/home/ubuntu/venv/lib/python3.8/site-packages/django/core/handlers/exception.py", line 47, in inner
    response = get_response(request)
  File "/home/ubuntu/venv/lib/python3.8/site-packages/django/core/handlers/base.py", line 204, in _get_response
    response = response.render()
  File "/home/ubuntu/venv/lib/python3.8/site-packages/django/template/response.py", line 105, in render
    self.content = self.rendered_content
  File "/home/ubuntu/venv/lib/python3.8/site-packages/django/template/response.py", line 83, in rendered_content
    return template.render(context, self._request)
  File "/home/ubuntu/venv/lib/python3.8/site-packages/django/template/backends/django.py", line 61, in render
    return self.template.render(context)
  File "/home/ubuntu/venv/lib/python3.8/site-packages/django/template/base.py", line 170, in render
    return self._render(context)
  File "/home/ubuntu/venv/lib/python3.8/site-packages/django/template/base.py", line 162, in _render
    return self.nodelist.render(context)
  File "/home/ubuntu/venv/lib/python3.8/site-packages/django/template/base.py", line 938, in render
    bit = node.render_annotated(context)
  File "/home/ubuntu/venv/lib/python3.8/site-packages/django/template/base.py", line 905, in render_annotated
    return self.render(context)
  File "/home/ubuntu/venv/lib/python3.8/site-packages/django/templatetags/static.py", line 106, in render
    url = self.url(context)
  File "/home/ubuntu/venv/lib/python3.8/site-packages/django/templatetags/static.py", line 103, in url
    return self.handle_simple(path)
  File "/home/ubuntu/venv/lib/python3.8/site-packages/django/templatetags/static.py", line 118, in handle_simple
    return staticfiles_storage.url(path)
  File "/home/ubuntu/venv/lib/python3.8/site-packages/django/contrib/staticfiles/storage.py", line 147, in url
    return self._url(self.stored_name, name, force)
  File "/home/ubuntu/venv/lib/python3.8/site-packages/django/contrib/staticfiles/storage.py", line 126, in _url
    hashed_name = hashed_name_func(*args)
  File "/home/ubuntu/venv/lib/python3.8/site-packages/django/contrib/staticfiles/storage.py", line 417, in stored_name
    raise ValueError("Missing staticfiles manifest entry for '%s'" % clean_name)
ValueError: Missing staticfiles manifest entry for 'images/favicon.png'
[24/May/2021 09:12:36] ERROR [django.request:224] Internal Server Error: /
Traceback (most recent call last):
  File "/home/ubuntu/venv/lib/python3.8/site-packages/django/core/handlers/exception.py", line 47, in inner
    response = get_response(request)
  File "/home/ubuntu/venv/lib/python3.8/site-packages/django/core/handlers/base.py", line 204, in _get_response
    response = response.render()
  File "/home/ubuntu/venv/lib/python3.8/site-packages/django/template/response.py", line 105, in render
    self.content = self.rendered_content
  File "/home/ubuntu/venv/lib/python3.8/site-packages/django/template/response.py", line 83, in rendered_content
    return template.render(context, self._request)
  File "/home/ubuntu/venv/lib/python3.8/site-packages/django/template/backends/django.py", line 61, in render
    return self.template.render(context)
  File "/home/ubuntu/venv/lib/python3.8/site-packages/django/template/base.py", line 170, in render
    return self._render(context)
  File "/home/ubuntu/venv/lib/python3.8/site-packages/django/template/base.py", line 162, in _render
    return self.nodelist.render(context)
  File "/home/ubuntu/venv/lib/python3.8/site-packages/django/template/base.py", line 938, in render
    bit = node.render_annotated(context)
  File "/home/ubuntu/venv/lib/python3.8/site-packages/django/template/base.py", line 905, in render_annotated
    return self.render(context)
  File "/home/ubuntu/venv/lib/python3.8/site-packages/django/templatetags/static.py", line 106, in render
    url = self.url(context)
  File "/home/ubuntu/venv/lib/python3.8/site-packages/django/templatetags/static.py", line 103, in url
    return self.handle_simple(path)
  File "/home/ubuntu/venv/lib/python3.8/site-packages/django/templatetags/static.py", line 118, in handle_simple
    return staticfiles_storage.url(path)
  File "/home/ubuntu/venv/lib/python3.8/site-packages/django/contrib/staticfiles/storage.py", line 147, in url
    return self._url(self.stored_name, name, force)
  File "/home/ubuntu/venv/lib/python3.8/site-packages/django/contrib/staticfiles/storage.py", line 126, in _url
    hashed_name = hashed_name_func(*args)
  File "/home/ubuntu/venv/lib/python3.8/site-packages/django/contrib/staticfiles/storage.py", line 417, in stored_name
    raise ValueError("Missing staticfiles manifest entry for '%s'" % clean_name)
ValueError: Missing staticfiles manifest entry for 'images/favicon.png'
[24/May/2021 09:14:36] ERROR [django.request:224] Internal Server Error: /
Traceback (most recent call last):
  File "/home/ubuntu/venv/lib/python3.8/site-packages/django/core/handlers/exception.py", line 47, in inner
    response = get_response(request)
  File "/home/ubuntu/venv/lib/python3.8/site-packages/django/core/handlers/base.py", line 204, in _get_response
    response = response.render()
  File "/home/ubuntu/venv/lib/python3.8/site-packages/django/template/response.py", line 105, in render
    self.content = self.rendered_content
  File "/home/ubuntu/venv/lib/python3.8/site-packages/django/template/response.py", line 83, in rendered_content
    return template.render(context, self._request)
  File "/home/ubuntu/venv/lib/python3.8/site-packages/django/template/backends/django.py", line 61, in render
    return self.template.render(context)
  File "/home/ubuntu/venv/lib/python3.8/site-packages/django/template/base.py", line 170, in render
    return self._render(context)
  File "/home/ubuntu/venv/lib/python3.8/site-packages/django/template/base.py", line 162, in _render
    return self.nodelist.render(context)
  File "/home/ubuntu/venv/lib/python3.8/site-packages/django/template/base.py", line 938, in render
    bit = node.render_annotated(context)
  File "/home/ubuntu/venv/lib/python3.8/site-packages/django/template/base.py", line 905, in render_annotated
    return self.render(context)
  File "/home/ubuntu/venv/lib/python3.8/site-packages/django/templatetags/static.py", line 106, in render
    url = self.url(context)
  File "/home/ubuntu/venv/lib/python3.8/site-packages/django/templatetags/static.py", line 103, in url
    return self.handle_simple(path)
  File "/home/ubuntu/venv/lib/python3.8/site-packages/django/templatetags/static.py", line 118, in handle_simple
    return staticfiles_storage.url(path)
  File "/home/ubuntu/venv/lib/python3.8/site-packages/django/contrib/staticfiles/storage.py", line 147, in url
    return self._url(self.stored_name, name, force)
  File "/home/ubuntu/venv/lib/python3.8/site-packages/django/contrib/staticfiles/storage.py", line 126, in _url
    hashed_name = hashed_name_func(*args)
  File "/home/ubuntu/venv/lib/python3.8/site-packages/django/contrib/staticfiles/storage.py", line 417, in stored_name
    raise ValueError("Missing staticfiles manifest entry for '%s'" % clean_name)
ValueError: Missing staticfiles manifest entry for 'images/favicon.png'
[24/May/2021 09:14:41] ERROR [django.request:224] Internal Server Error: /
Traceback (most recent call last):
  File "/home/ubuntu/venv/lib/python3.8/site-packages/django/core/handlers/exception.py", line 47, in inner
    response = get_response(request)
  File "/home/ubuntu/venv/lib/python3.8/site-packages/django/core/handlers/base.py", line 204, in _get_response
    response = response.render()
  File "/home/ubuntu/venv/lib/python3.8/site-packages/django/template/response.py", line 105, in render
    self.content = self.rendered_content
  File "/home/ubuntu/venv/lib/python3.8/site-packages/django/template/response.py", line 83, in rendered_content
    return template.render(context, self._request)
  File "/home/ubuntu/venv/lib/python3.8/site-packages/django/template/backends/django.py", line 61, in render
    return self.template.render(context)
  File "/home/ubuntu/venv/lib/python3.8/site-packages/django/template/base.py", line 170, in render
    return self._render(context)
  File "/home/ubuntu/venv/lib/python3.8/site-packages/django/template/base.py", line 162, in _render
    return self.nodelist.render(context)
  File "/home/ubuntu/venv/lib/python3.8/site-packages/django/template/base.py", line 938, in render
    bit = node.render_annotated(context)
  File "/home/ubuntu/venv/lib/python3.8/site-packages/django/template/base.py", line 905, in render_annotated
    return self.render(context)
  File "/home/ubuntu/venv/lib/python3.8/site-packages/django/templatetags/static.py", line 106, in render
    url = self.url(context)
  File "/home/ubuntu/venv/lib/python3.8/site-packages/django/templatetags/static.py", line 103, in url
    return self.handle_simple(path)
  File "/home/ubuntu/venv/lib/python3.8/site-packages/django/templatetags/static.py", line 118, in handle_simple
    return staticfiles_storage.url(path)
  File "/home/ubuntu/venv/lib/python3.8/site-packages/django/contrib/staticfiles/storage.py", line 147, in url
    return self._url(self.stored_name, name, force)
  File "/home/ubuntu/venv/lib/python3.8/site-packages/django/contrib/staticfiles/storage.py", line 126, in _url
    hashed_name = hashed_name_func(*args)
  File "/home/ubuntu/venv/lib/python3.8/site-packages/django/contrib/staticfiles/storage.py", line 417, in stored_name
    raise ValueError("Missing staticfiles manifest entry for '%s'" % clean_name)
ValueError: Missing staticfiles manifest entry for 'images/favicon.png'
[24/May/2021 09:29:48] ERROR [django.request:224] Internal Server Error: /
Traceback (most recent call last):
  File "/home/ubuntu/venv/lib/python3.8/site-packages/django/core/handlers/exception.py", line 47, in inner
    response = get_response(request)
  File "/home/ubuntu/venv/lib/python3.8/site-packages/django/core/handlers/base.py", line 204, in _get_response
    response = response.render()
  File "/home/ubuntu/venv/lib/python3.8/site-packages/django/template/response.py", line 105, in render
    self.content = self.rendered_content
  File "/home/ubuntu/venv/lib/python3.8/site-packages/django/template/response.py", line 83, in rendered_content
    return template.render(context, self._request)
  File "/home/ubuntu/venv/lib/python3.8/site-packages/django/template/backends/django.py", line 61, in render
    return self.template.render(context)
  File "/home/ubuntu/venv/lib/python3.8/site-packages/django/template/base.py", line 170, in render
    return self._render(context)
  File "/home/ubuntu/venv/lib/python3.8/site-packages/django/template/base.py", line 162, in _render
    return self.nodelist.render(context)
  File "/home/ubuntu/venv/lib/python3.8/site-packages/django/template/base.py", line 938, in render
    bit = node.render_annotated(context)
  File "/home/ubuntu/venv/lib/python3.8/site-packages/django/template/base.py", line 905, in render_annotated
    return self.render(context)
  File "/home/ubuntu/venv/lib/python3.8/site-packages/django/templatetags/static.py", line 106, in render
    url = self.url(context)
  File "/home/ubuntu/venv/lib/python3.8/site-packages/django/templatetags/static.py", line 103, in url
    return self.handle_simple(path)
  File "/home/ubuntu/venv/lib/python3.8/site-packages/django/templatetags/static.py", line 118, in handle_simple
    return staticfiles_storage.url(path)
  File "/home/ubuntu/venv/lib/python3.8/site-packages/django/contrib/staticfiles/storage.py", line 147, in url
    return self._url(self.stored_name, name, force)
  File "/home/ubuntu/venv/lib/python3.8/site-packages/django/contrib/staticfiles/storage.py", line 126, in _url
    hashed_name = hashed_name_func(*args)
  File "/home/ubuntu/venv/lib/python3.8/site-packages/django/contrib/staticfiles/storage.py", line 417, in stored_name
    raise ValueError("Missing staticfiles manifest entry for '%s'" % clean_name)
ValueError: Missing staticfiles manifest entry for 'images/favicon.png'
[24/May/2021 09:53:04] ERROR [django.request:224] Internal Server Error: /
Traceback (most recent call last):
  File "/home/ubuntu/venv/lib/python3.8/site-packages/django/core/handlers/exception.py", line 47, in inner
    response = get_response(request)
  File "/home/ubuntu/venv/lib/python3.8/site-packages/django/core/handlers/base.py", line 204, in _get_response
    response = response.render()
  File "/home/ubuntu/venv/lib/python3.8/site-packages/django/template/response.py", line 105, in render
    self.content = self.rendered_content
  File "/home/ubuntu/venv/lib/python3.8/site-packages/django/template/response.py", line 83, in rendered_content
    return template.render(context, self._request)
  File "/home/ubuntu/venv/lib/python3.8/site-packages/django/template/backends/django.py", line 61, in render
    return self.template.render(context)
  File "/home/ubuntu/venv/lib/python3.8/site-packages/django/template/base.py", line 170, in render
    return self._render(context)
  File "/home/ubuntu/venv/lib/python3.8/site-packages/django/template/base.py", line 162, in _render
    return self.nodelist.render(context)
  File "/home/ubuntu/venv/lib/python3.8/site-packages/django/template/base.py", line 938, in render
    bit = node.render_annotated(context)
  File "/home/ubuntu/venv/lib/python3.8/site-packages/django/template/base.py", line 905, in render_annotated
    return self.render(context)
  File "/home/ubuntu/venv/lib/python3.8/site-packages/django/templatetags/static.py", line 106, in render
    url = self.url(context)
  File "/home/ubuntu/venv/lib/python3.8/site-packages/django/templatetags/static.py", line 103, in url
    return self.handle_simple(path)
  File "/home/ubuntu/venv/lib/python3.8/site-packages/django/templatetags/static.py", line 118, in handle_simple
    return staticfiles_storage.url(path)
  File "/home/ubuntu/venv/lib/python3.8/site-packages/django/contrib/staticfiles/storage.py", line 147, in url
    return self._url(self.stored_name, name, force)
  File "/home/ubuntu/venv/lib/python3.8/site-packages/django/contrib/staticfiles/storage.py", line 126, in _url
    hashed_name = hashed_name_func(*args)
  File "/home/ubuntu/venv/lib/python3.8/site-packages/django/contrib/staticfiles/storage.py", line 417, in stored_name
    raise ValueError("Missing staticfiles manifest entry for '%s'" % clean_name)
ValueError: Missing staticfiles manifest entry for 'images/favicon.png'
[24/May/2021 11:20:24] DEBUG [django.db.backends.schema:136] CREATE TABLE "django_migrations" ("id" bigserial NOT NULL PRIMARY KEY, "app" varchar(255) NOT NULL, "name" varchar(255) NOT NULL, "applied" timestamp with time zone NOT NULL); (params None)
[24/May/2021 11:20:24] DEBUG [django.db.backends.schema:136] CREATE TABLE "django_content_type" ("id" serial NOT NULL PRIMARY KEY, "name" varchar(100) NOT NULL, "app_label" varchar(100) NOT NULL, "model" varchar(100) NOT NULL); (params None)
[24/May/2021 11:20:24] DEBUG [django.db.backends.schema:136] ALTER TABLE "django_content_type" ADD CONSTRAINT "django_content_type_app_label_model_76bd3d3b_uniq" UNIQUE ("app_label", "model"); (params ())
[24/May/2021 11:20:24] DEBUG [django.db.backends.schema:136] CREATE TABLE "auth_permission" ("id" serial NOT NULL PRIMARY KEY, "name" varchar(50) NOT NULL, "content_type_id" integer NOT NULL, "codename" varchar(100) NOT NULL); (params None)
[24/May/2021 11:20:24] DEBUG [django.db.backends.schema:136] CREATE TABLE "auth_group" ("id" serial NOT NULL PRIMARY KEY, "name" varchar(80) NOT NULL UNIQUE); (params None)
[24/May/2021 11:20:24] DEBUG [django.db.backends.schema:136] CREATE TABLE "auth_group_permissions" ("id" bigserial NOT NULL PRIMARY KEY, "group_id" integer NOT NULL, "permission_id" integer NOT NULL); (params None)
[24/May/2021 11:20:24] DEBUG [django.db.backends.schema:136] CREATE TABLE "auth_user" ("id" serial NOT NULL PRIMARY KEY, "password" varchar(128) NOT NULL, "last_login" timestamp with time zone NOT NULL, "is_superuser" boolean NOT NULL, "username" varchar(30) NOT NULL UNIQUE, "first_name" varchar(30) NOT NULL, "last_name" varchar(30) NOT NULL, "email" varchar(75) NOT NULL, "is_staff" boolean NOT NULL, "is_active" boolean NOT NULL, "date_joined" timestamp with time zone NOT NULL); (params None)
[24/May/2021 11:20:24] DEBUG [django.db.backends.schema:136] CREATE TABLE "auth_user_groups" ("id" bigserial NOT NULL PRIMARY KEY, "user_id" integer NOT NULL, "group_id" integer NOT NULL); (params None)
[24/May/2021 11:20:24] DEBUG [django.db.backends.schema:136] CREATE TABLE "auth_user_user_permissions" ("id" bigserial NOT NULL PRIMARY KEY, "user_id" integer NOT NULL, "permission_id" integer NOT NULL); (params None)
[24/May/2021 11:20:24] DEBUG [django.db.backends.schema:136] ALTER TABLE "auth_permission" ADD CONSTRAINT "auth_permission_content_type_id_codename_01ab375a_uniq" UNIQUE ("content_type_id", "codename"); (params ())
[24/May/2021 11:20:24] DEBUG [django.db.backends.schema:136] ALTER TABLE "auth_permission" ADD CONSTRAINT "auth_permission_content_type_id_2f476e4b_fk_django_co" FOREIGN KEY ("content_type_id") REFERENCES "django_content_type" ("id") DEFERRABLE INITIALLY DEFERRED; (params ())
[24/May/2021 11:20:24] DEBUG [django.db.backends.schema:136] CREATE INDEX "auth_permission_content_type_id_2f476e4b" ON "auth_permission" ("content_type_id"); (params ())
[24/May/2021 11:20:24] DEBUG [django.db.backends.schema:136] CREATE INDEX "auth_group_name_a6ea08ec_like" ON "auth_group" ("name" varchar_pattern_ops); (params ())
[24/May/2021 11:20:24] DEBUG [django.db.backends.schema:136] ALTER TABLE "auth_group_permissions" ADD CONSTRAINT "auth_group_permissions_group_id_permission_id_0cd325b0_uniq" UNIQUE ("group_id", "permission_id"); (params ())
[24/May/2021 11:20:24] DEBUG [django.db.backends.schema:136] ALTER TABLE "auth_group_permissions" ADD CONSTRAINT "auth_group_permissions_group_id_b120cbf9_fk_auth_group_id" FOREIGN KEY ("group_id") REFERENCES "auth_group" ("id") DEFERRABLE INITIALLY DEFERRED; (params ())
[24/May/2021 11:20:24] DEBUG [django.db.backends.schema:136] ALTER TABLE "auth_group_permissions" ADD CONSTRAINT "auth_group_permissio_permission_id_84c5c92e_fk_auth_perm" FOREIGN KEY ("permission_id") REFERENCES "auth_permission" ("id") DEFERRABLE INITIALLY DEFERRED; (params ())
[24/May/2021 11:20:24] DEBUG [django.db.backends.schema:136] CREATE INDEX "auth_group_permissions_group_id_b120cbf9" ON "auth_group_permissions" ("group_id"); (params ())
[24/May/2021 11:20:24] DEBUG [django.db.backends.schema:136] CREATE INDEX "auth_group_permissions_permission_id_84c5c92e" ON "auth_group_permissions" ("permission_id"); (params ())
[24/May/2021 11:20:24] DEBUG [django.db.backends.schema:136] CREATE INDEX "auth_user_username_6821ab7c_like" ON "auth_user" ("username" varchar_pattern_ops); (params ())
[24/May/2021 11:20:24] DEBUG [django.db.backends.schema:136] ALTER TABLE "auth_user_groups" ADD CONSTRAINT "auth_user_groups_user_id_group_id_94350c0c_uniq" UNIQUE ("user_id", "group_id"); (params ())
[24/May/2021 11:20:24] DEBUG [django.db.backends.schema:136] ALTER TABLE "auth_user_groups" ADD CONSTRAINT "auth_user_groups_user_id_6a12ed8b_fk_auth_user_id" FOREIGN KEY ("user_id") REFERENCES "auth_user" ("id") DEFERRABLE INITIALLY DEFERRED; (params ())
[24/May/2021 11:20:24] DEBUG [django.db.backends.schema:136] ALTER TABLE "auth_user_groups" ADD CONSTRAINT "auth_user_groups_group_id_97559544_fk_auth_group_id" FOREIGN KEY ("group_id") REFERENCES "auth_group" ("id") DEFERRABLE INITIALLY DEFERRED; (params ())
[24/May/2021 11:20:24] DEBUG [django.db.backends.schema:136] CREATE INDEX "auth_user_groups_user_id_6a12ed8b" ON "auth_user_groups" ("user_id"); (params ())
[24/May/2021 11:20:24] DEBUG [django.db.backends.schema:136] CREATE INDEX "auth_user_groups_group_id_97559544" ON "auth_user_groups" ("group_id"); (params ())
[24/May/2021 11:20:24] DEBUG [django.db.backends.schema:136] ALTER TABLE "auth_user_user_permissions" ADD CONSTRAINT "auth_user_user_permissions_user_id_permission_id_14a6b632_uniq" UNIQUE ("user_id", "permission_id"); (params ())
[24/May/2021 11:20:24] DEBUG [django.db.backends.schema:136] ALTER TABLE "auth_user_user_permissions" ADD CONSTRAINT "auth_user_user_permissions_user_id_a95ead1b_fk_auth_user_id" FOREIGN KEY ("user_id") REFERENCES "auth_user" ("id") DEFERRABLE INITIALLY DEFERRED; (params ())
[24/May/2021 11:20:24] DEBUG [django.db.backends.schema:136] ALTER TABLE "auth_user_user_permissions" ADD CONSTRAINT "auth_user_user_permi_permission_id_1fbb5f2c_fk_auth_perm" FOREIGN KEY ("permission_id") REFERENCES "auth_permission" ("id") DEFERRABLE INITIALLY DEFERRED; (params ())
[24/May/2021 11:20:24] DEBUG [django.db.backends.schema:136] CREATE INDEX "auth_user_user_permissions_user_id_a95ead1b" ON "auth_user_user_permissions" ("user_id"); (params ())
[24/May/2021 11:20:24] DEBUG [django.db.backends.schema:136] CREATE INDEX "auth_user_user_permissions_permission_id_1fbb5f2c" ON "auth_user_user_permissions" ("permission_id"); (params ())
[24/May/2021 11:20:24] DEBUG [django.db.backends.schema:136] CREATE TABLE "django_admin_log" ("id" serial NOT NULL PRIMARY KEY, "action_time" timestamp with time zone NOT NULL, "object_id" text NULL, "object_repr" varchar(200) NOT NULL, "action_flag" smallint NOT NULL CHECK ("action_flag" >= 0), "change_message" text NOT NULL, "content_type_id" integer NULL, "user_id" integer NOT NULL); (params None)
[24/May/2021 11:20:24] DEBUG [django.db.backends.schema:136] ALTER TABLE "django_admin_log" ADD CONSTRAINT "django_admin_log_content_type_id_c4bce8eb_fk_django_co" FOREIGN KEY ("content_type_id") REFERENCES "django_content_type" ("id") DEFERRABLE INITIALLY DEFERRED; (params ())
[24/May/2021 11:20:24] DEBUG [django.db.backends.schema:136] ALTER TABLE "django_admin_log" ADD CONSTRAINT "django_admin_log_user_id_c564eba6_fk_auth_user_id" FOREIGN KEY ("user_id") REFERENCES "auth_user" ("id") DEFERRABLE INITIALLY DEFERRED; (params ())
[24/May/2021 11:20:24] DEBUG [django.db.backends.schema:136] CREATE INDEX "django_admin_log_content_type_id_c4bce8eb" ON "django_admin_log" ("content_type_id"); (params ())
[24/May/2021 11:20:24] DEBUG [django.db.backends.schema:136] CREATE INDEX "django_admin_log_user_id_c564eba6" ON "django_admin_log" ("user_id"); (params ())
[24/May/2021 11:20:24] DEBUG [django.db.backends.schema:136] ALTER TABLE "django_content_type" ALTER COLUMN "name" DROP NOT NULL; (params [])
[24/May/2021 11:20:24] DEBUG [django.db.backends.schema:136] ALTER TABLE "django_content_type" DROP COLUMN "name" CASCADE; (params ())
[24/May/2021 11:20:24] DEBUG [django.db.backends.schema:136] ALTER TABLE "auth_permission" ALTER COLUMN "name" TYPE varchar(255); (params [])
[24/May/2021 11:20:24] DEBUG [django.db.backends.schema:136] ALTER TABLE "auth_user" ALTER COLUMN "email" TYPE varchar(254); (params [])
[24/May/2021 11:20:24] DEBUG [django.db.backends.schema:136] ALTER TABLE "auth_user" ALTER COLUMN "last_login" DROP NOT NULL; (params [])
[24/May/2021 11:20:24] DEBUG [django.db.backends.schema:136] ALTER TABLE "auth_user" ALTER COLUMN "username" TYPE varchar(150); (params [])
[24/May/2021 11:20:24] DEBUG [django.db.backends.schema:136] ALTER TABLE "auth_user" ALTER COLUMN "last_name" TYPE varchar(150); (params [])
[24/May/2021 11:20:24] DEBUG [django.db.backends.schema:136] ALTER TABLE "auth_group" ALTER COLUMN "name" TYPE varchar(150); (params [])
[24/May/2021 11:20:24] DEBUG [django.db.backends.schema:136] ALTER TABLE "auth_user" ALTER COLUMN "first_name" TYPE varchar(150); (params [])
[24/May/2021 11:20:24] DEBUG [django.db.backends.schema:136] CREATE TABLE "django_session" ("session_key" varchar(40) NOT NULL PRIMARY KEY, "session_data" text NOT NULL, "expire_date" timestamp with time zone NOT NULL); (params None)
[24/May/2021 11:20:24] DEBUG [django.db.backends.schema:136] CREATE INDEX "django_session_session_key_c0390e0f_like" ON "django_session" ("session_key" varchar_pattern_ops); (params ())
[24/May/2021 11:20:24] DEBUG [django.db.backends.schema:136] CREATE INDEX "django_session_expire_date_a5c62663" ON "django_session" ("expire_date"); (params ())
[24/May/2021 11:20:39] DEBUG [django.db.backends.schema:136] CREATE TABLE "introduction_galleryimage" ("id" bigserial NOT NULL PRIMARY KEY, "image" varchar(100) NOT NULL, "alt" varchar(100) NOT NULL); (params None)
